<?xml version="1.0" encoding="utf-8" ?>

<robot name="fr3" xmlns:xacro="http://ros.org/wiki/xacro">
    <link name="base_link">
        
<inertial>
            <origin rpy="0 0 0" xyz="-0.00049027 -0.00045095 0.032527" />
            <mass value="0.78393" />
            <inertia ixx="0.0013854" ixy="1.1455E-05" ixz="-1.0642E-05" iyy="0.0013849" iyz="-9.7435E-06" izz="0.001977" />
        </inertial>

        <visual>
            <origin rpy="0 0 0" xyz="0 0 0" />
            <geometry>
                <mesh filename="package://frcobot_description/meshes/fr3v6/visual/base_link.STL" />
            </geometry>
            <material name="">
                <color rgba="0.89804 0.91765 0.92941 1" />
            </material>
        </visual>
        <collision>
            <origin rpy="0 0 0" xyz="0 0 0" />
            <geometry>
                <mesh filename="package://frcobot_description/meshes/fr3v6/visual/base_link.STL" />
            </geometry>
        </collision>
    </link>
    <link name="link1">
        
<inertial>
            <origin rpy="0 0 0" xyz="-3.8658E-07 -0.0024176 0.13519" />
            <mass value="0.021225" />
            <inertia ixx="0.0033227" ixy="-5.0648E-08" ixz="-6.3401E-09" iyy="0.0032419" iyz="4.3768E-05" izz="0.0023129" />
        </inertial>

        <visual>
            <origin rpy="0 0 0" xyz="0 0 0" />
            <geometry>
                <mesh filename="package://frcobot_description/meshes/fr3v6/visual/link1.STL" />
            </geometry>
            <material name="">
                <color rgba="0.89804 0.91765 0.92941 1" />
            </material>
        </visual>
        <collision>
            <origin rpy="0 0 0" xyz="0 0 0" />
            <geometry>
                <mesh filename="package://frcobot_description/meshes/fr3v6/visual/link1.STL" />
            </geometry>
        </collision>
    </link>
    <joint name="joint1" type="revolute">
        <origin rpy="0 0 0" xyz="0 0 0" />
        <parent link="base_link" />
        <child link="link1" />
        <axis xyz="0 0 1" />
        <limit effort="28" lower="-3.14" upper="3.14" velocity="3.2" />
    </joint>
    <link name="link2">
        
<inertial>
            <origin rpy="0 0 0" xyz="-0.14111 3.4656E-06 0.11053" />
            <mass value="0.048053" />
            <inertia ixx="0.0075945" ixy="3.7143E-07" ixz="-7.9228E-12" iyy="0.0081317" iyz="-1.2918E-11" izz="0.0059231" />
        </inertial>

        <visual>
            <origin rpy="0 0 0" xyz="0 0 0" />
            <geometry>
                <mesh filename="package://frcobot_description/meshes/fr3v6/visual/link2.STL" />
            </geometry>
            <material name="">
                <color rgba="0.89804 0.91765 0.92941 1" />
            </material>
        </visual>
        <collision>
            <origin rpy="0 0 0" xyz="0 0 0" />
            <geometry>
                <mesh filename="package://frcobot_description/meshes/fr3v6/visual/link2.STL" />
            </geometry>
        </collision>
    </link>
    <joint name="joint2" type="revolute">
        <origin rpy="1.5708 0 0" xyz="0 0 0.1407034" />
        <parent link="link1" />
        <child link="link2" />
        <axis xyz="0 0 1" />
        <limit effort="28" lower="-3.14" upper="3.14" velocity="3.2" />
    </joint>
    <link name="link3">
        
<inertial>
            <origin rpy="0 0 0" xyz="-0.18987 5.2268E-06 0.0034145" />
            <mass value="0.022312" />
            <inertia ixx="0.0028852" ixy="7.3389E-07" ixz="-3.5373E-05" iyy="0.0035145" iyz="-2.8527E-07" izz="0.0029186" />
        </inertial>

        <visual>
            <origin rpy="0 0 0" xyz="0 0 0" />
            <geometry>
                <mesh filename="package://frcobot_description/meshes/fr3v6/visual/link3.STL" />
            </geometry>
            <material name="">
                <color rgba="0.89804 0.91765 0.92941 1" />
            </material>
        </visual>
        <collision>
            <origin rpy="0 0 0" xyz="0 0 0" />
            <geometry>
                <mesh filename="package://frcobot_description/meshes/fr3v6/visual/link3.STL" />
            </geometry>
        </collision>
    </link>
    <joint name="joint3" type="revolute">
        <origin rpy="0 0 0" xyz="-0.2802789 0 0" />
        <parent link="link2" />
        <child link="link3" />
        <axis xyz="0 0 1" />
        <limit effort="28" lower="-3.14" upper="3.14" velocity="3.2" />
    </joint>
    <link name="link4">
        
<inertial>
            <origin rpy="0 0 0" xyz="4.5665E-07 -0.0034666 0.098292" />
            <mass value="0.015961" />
            <inertia ixx="0.0020112" ixy="6.8085E-09" ixz="2.4945E-08" iyy="0.0014524" iyz="3.2511E-05" izz="0.0019076" />
        </inertial>

        <visual>
            <origin rpy="0 0 0" xyz="0 0 0" />
            <geometry>
                <mesh filename="package://frcobot_description/meshes/fr3v6/visual/link4.STL" />
            </geometry>
            <material name="">
                <color rgba="0.89804 0.91765 0.92941 1" />
            </material>
        </visual>
        <collision>
            <origin rpy="0 0 0" xyz="0 0 0" />
            <geometry>
                <mesh filename="package://frcobot_description/meshes/fr3v6/visual/link4.STL" />
            </geometry>
        </collision>
    </link>
    <joint name="joint4" type="revolute">
        <origin rpy="0 0 0" xyz="-0.2413385 0 0" />
        <parent link="link3" />
        <child link="link4" />
        <axis xyz="0 0 1" />
        <limit effort="28" lower="-3.14" upper="3.14" velocity="3.2" />
    </joint>
    <link name="link5">
        
<inertial>
            <origin rpy="0 0 0" xyz="-4.5262E-07 0.0034666 0.098292" />
            <mass value="0.015961" />
            <inertia ixx="0.0020112" ixy="6.8086E-09" ixz="-2.4945E-08" iyy="0.0014524" iyz="-3.2511E-05" izz="0.0019076" />
        </inertial>

        <visual>
            <origin rpy="0 0 0" xyz="0 0 0" />
            <geometry>
                <mesh filename="package://frcobot_description/meshes/fr3v6/visual/link5.STL" />
            </geometry>
            <material name="">
                <color rgba="0.89804 0.91765 0.92941 1" />
            </material>
        </visual>
        <collision>
            <origin rpy="0 0 0" xyz="0 0 0" />
            <geometry>
                <mesh filename="package://frcobot_description/meshes/fr3v6/visual/link5.STL" />
            </geometry>
        </collision>
    </link>
    <joint name="joint5" type="revolute">
        <origin rpy="1.5708 0 0" xyz="0 0 0.1034055" />
        <parent link="link4" />
        <child link="link5" />
        <axis xyz="0 0 1" />
        <limit effort="28" lower="-3.14" upper="3.14" velocity="3.2" />
    </joint>
    <link name="link6">
        
<inertial>
            <origin rpy="0 0 0" xyz="7.559E-05 1.3858E-05 0.076619" />
            <mass value="0.053877" />
            <inertia ixx="0.00028785" ixy="-2.0584E-09" ixz="-1.3892E-07" iyy="0.00028896" iyz="1.8115E-07" izz="0.00042655" />
        </inertial>

        <visual>
            <origin rpy="0 0 0" xyz="0 0 0" />
            <geometry>
                <mesh filename="package://frcobot_description/meshes/fr3v6/visual/link6.STL" />
            </geometry>
            <material name="">
                <color rgba="0.89804 0.91765 0.92941 1" />
            </material>
        </visual>
        <collision>
            <origin rpy="0 0 0" xyz="0 0 0" />
            <geometry>
                <mesh filename="package://frcobot_description/meshes/fr3v6/visual/link6.STL" />
            </geometry>
        </collision>
    </link>
    <joint name="joint6" type="revolute">
        <origin rpy="-1.5708 0 0" xyz="0 0 0.1024258" />
        <parent link="link5" />
        <child link="link6" />
        <axis xyz="0 0 1" />
        <limit effort="28" lower="-3.14" upper="3.14" velocity="3.2" />
    </joint>
    <!--gripper-->
    <link name="gripper_base_link">
        
<inertial>
            <origin xyz="-0.0004684975887838 0.00303048592831926 0.0502886435926091" rpy="0 0 0" />
            <mass value="0.0338451530379819" />
            <inertia ixx="0.000176005566867876" ixy="-6.64408835735538E-09" ixz="1.13135832689069E-07" iyy="0.000237259038170363" iyz="1.89171837600438E-06" izz="0.000213929505027592" />
        </inertial>

        <visual>
            <origin xyz="0 0 0" rpy="0 0 0" />
            <geometry>
                <mesh filename="package://gripper_description/meshes/base_link.STL" />
            </geometry>
            <material name="">
                <color rgba="1 1 1 1" />
            </material>
        </visual>
        <collision>
            <origin xyz="0 0 0" rpy="0 0 0" />
            <geometry>
                <mesh filename="package://gripper_description/meshes/base_link.STL" />
            </geometry>
        </collision>
    </link>
    <link name="Gripper_Link1">
        
<inertial>
            <origin xyz="0.0280069393107553 0.00611122757021528 -0.00200684068788289" rpy="0 0 0" />
            <mass value="0.00252253473341853" />
            <inertia ixx="3.64693126790912E-06" ixy="-1.25306744959638E-08" ixz="-6.52209709686841E-07" iyy="7.00716884133288E-06" iyz="1.03549055739974E-07" izz="4.79349978637373E-06" />
        </inertial>

        <visual>
            <origin xyz="0 0 0" rpy="0 0 0" />
            <geometry>
                <mesh filename="package://gripper_description/meshes/Gripper_Link1.STL" />
            </geometry>
            <material name="">
                <color rgba="1 1 1 1" />
            </material>
        </visual>
        <collision>
            <origin xyz="0 0 0" rpy="0 0 0" />
            <geometry>
                <mesh filename="package://gripper_description/meshes/Gripper_Link1.STL" />
            </geometry>
        </collision>
    </link>
    <joint name="Gripper_Joint1" type="prismatic">
        <origin xyz="0.00947 -0.009 0.10472" rpy="0 -1.5708 0" />
        <parent link="gripper_base_link" />
        <child link="Gripper_Link1" />
        <axis xyz="0 0 1" />
        <limit lower="-1" upper="1" effort="1" velocity="1" />
    </joint>
    <link name="Gripper_Link2">
        
<inertial>
            <origin xyz="0.0280069393107553 0.00611122757021521 -0.00200684068788287" rpy="0 0 0" />
            <mass value="0.00252253473341853" />
            <inertia ixx="3.64693126790912E-06" ixy="-1.25306744959344E-08" ixz="-6.52209709686843E-07" iyy="7.00716884133288E-06" iyz="1.03549055739979E-07" izz="4.79349978637373E-06" />
        </inertial>

        <visual>
            <origin xyz="0 0 0" rpy="0 0 0" />
            <geometry>
                <mesh filename="package://gripper_description/meshes/Gripper_Link2.STL" />
            </geometry>
            <material name="">
                <color rgba="1 1 1 1" />
            </material>
        </visual>
        <collision>
            <origin xyz="0 0 0" rpy="0 0 0" />
            <geometry>
                <mesh filename="package://gripper_description/meshes/Gripper_Link2.STL" />
            </geometry>
        </collision>
    </link>
    <joint name="Gripper_Joint2" type="prismatic">
        <origin xyz="-0.00947 0.009 0.10472" rpy="3.1416 -1.5708 0" />
        <parent link="gripper_base_link" />
        <child link="Gripper_Link2" />
        <axis xyz="0 0 1" />
        <limit lower="-1" upper="1" effort="1" velocity="1" />
    </joint>
    <link name="Camera_Link3">
        
<inertial>
            <origin xyz="-6.45917661786042E-06 -2.58386344099554E-05 0.0147332789871856" rpy="0 0 0" />
            <mass value="0.00547058531734444" />
            <inertia ixx="6.23440458905677E-06" ixy="4.47738142991786E-11" ixz="5.1211068270788E-09" iyy="3.30237698271353E-05" iyz="2.48412900210222E-08" izz="3.17409016851319E-05" />
        </inertial>

        <visual>
            <origin xyz="0 0 0" rpy="0 0 0" />
            <geometry>
                <mesh filename="package://gripper_description/meshes/Camera_Link3.STL" />
            </geometry>
            <material name="">
                <color rgba="1 1 1 1" />
            </material>
        </visual>
        <collision>
            <origin xyz="0 0 0" rpy="0 0 0" />
            <geometry>
                <mesh filename="package://gripper_description/meshes/Camera_Link3.STL" />
            </geometry>
        </collision>
    </link>
    <joint name="Camera_Joint3" type="fixed">
        <origin xyz="0 0.08948 0.05452" rpy="0 0 0" />
        <parent link="gripper_base_link" />
        <child link="Camera_Link3" />
        <axis xyz="0 0 0" />
    </joint>
    <joint name="gripper_joint" type="fixed">
        <parent link="link6" />
        <child link="gripper_base_link" />
        <origin xyz="0 0 0.09" rpy="0 0 0" />
    </joint>
    <link name="world" />
    <joint name="world_joint" type="fixed">
        <parent link="world" />
        <child link="base_link" />
        <origin xyz="0 0 0.15" rpy="0.0 0.0 0.0" />
    </joint>

    <gazebo reference="gripper_base_link">
        <material>Gazebo/Grey</material>
    </gazebo>

    <gazebo reference="Gripper_Link2">
        <material>Gazebo/Grey</material>
    </gazebo>

    <gazebo reference="Gripper_Link1">
        <material>Gazebo/Grey</material>
    </gazebo>

    <!-- add camera-->
    <link name="camera_link">
        <origin rpy="0 0 0" xyz="0 0 0" />
        <visual>
            <origin rpy="1.57 0 1.57" xyz="0 0 0" />
            <geometry>
                <mesh filename="package://frcobot_description/meshes/d435i.dae" />
            </geometry>
        </visual>
        <!-- <collision>
        <geometry>
          <box size="0.07 0.3 0.09"/>
        </geometry>
      </collision> -->
    </link>
    <joint name="camera_optical_joint" type="fixed">
        <origin rpy="-1.5708 0 -1.5708" xyz="0 0 0" />
        <parent link="camera_link" />
        <child link="camera_frame_optical" />
    </joint>
    <link name="camera_frame_optical" />
    <joint name="camera_joint" type="fixed">
        <origin rpy="3.1415 1.5708 0" xyz="-0.3 0.0 0.7" />
        <parent link="base_link" />
        <child link="camera_link" />
    </joint>
    <gazebo reference="camera_link">
        <sensor name="camera" type="depth">
            <always_on>true</always_on>
            <update_rate>20.0</update_rate>
            <camera>
                <horizontal_fov>1.04</horizontal_fov>
                <image>
                    <format>R8G8B8</format>
                    <width>640</width>
                    <height>480</height>
                </image>
                <clip>
                    <near>0.05</near>
                    <far>8.0</far>
                </clip>
            </camera>
            <plugin filename="libgazebo_ros_openni_kinect.so" name="kinect_camera_controller">
                <cameraName>/camera</cameraName>
                <alwaysOn>true</alwaysOn>
                <updateRate>10</updateRate>
                <imageTopicName>rgb/image_raw</imageTopicName>
                <depthImageTopicName>depth/image_raw</depthImageTopicName>
                <pointCloudTopicName>depth/points</pointCloudTopicName>
                <cameraInfoTopicName>rgb/camera_info</cameraInfoTopicName>
                <depthImageCameraInfoTopicName>depth/camera_info</depthImageCameraInfoTopicName>
                <frameName>camera_frame_optical</frameName>
                <baseline>0.1</baseline>
                <distortion_k1>0.0</distortion_k1>
                <distortion_k2>0.0</distortion_k2>
                <distortion_k3>0.0</distortion_k3>
                <distortion_t1>0.0</distortion_t1>
                <distortion_t2>0.0</distortion_t2>
                <pointCloudCutoff>0.05</pointCloudCutoff>
            </plugin>
        </sensor>
    </gazebo>

<transmission name="trans_joint1">
        <type>transmission_interface/SimpleTransmission</type>
        <joint name="joint1">
            <hardwareInterface>hardware_interface/PositionJointInterface</hardwareInterface>
        </joint>
        <actuator name="joint1_motor">
            <hardwareInterface>hardware_interface/PositionJointInterface</hardwareInterface>
            <mechanicalReduction>1</mechanicalReduction>
        </actuator>
    </transmission>
    <transmission name="trans_joint2">
        <type>transmission_interface/SimpleTransmission</type>
        <joint name="joint2">
            <hardwareInterface>hardware_interface/PositionJointInterface</hardwareInterface>
        </joint>
        <actuator name="joint2_motor">
            <hardwareInterface>hardware_interface/PositionJointInterface</hardwareInterface>
            <mechanicalReduction>1</mechanicalReduction>
        </actuator>
    </transmission>
    <transmission name="trans_joint3">
        <type>transmission_interface/SimpleTransmission</type>
        <joint name="joint3">
            <hardwareInterface>hardware_interface/PositionJointInterface</hardwareInterface>
        </joint>
        <actuator name="joint3_motor">
            <hardwareInterface>hardware_interface/PositionJointInterface</hardwareInterface>
            <mechanicalReduction>1</mechanicalReduction>
        </actuator>
    </transmission>
    <transmission name="trans_joint4">
        <type>transmission_interface/SimpleTransmission</type>
        <joint name="joint4">
            <hardwareInterface>hardware_interface/PositionJointInterface</hardwareInterface>
        </joint>
        <actuator name="joint4_motor">
            <hardwareInterface>hardware_interface/PositionJointInterface</hardwareInterface>
            <mechanicalReduction>1</mechanicalReduction>
        </actuator>
    </transmission>
    <transmission name="trans_joint5">
        <type>transmission_interface/SimpleTransmission</type>
        <joint name="joint5">
            <hardwareInterface>hardware_interface/PositionJointInterface</hardwareInterface>
        </joint>
        <actuator name="joint5_motor">
            <hardwareInterface>hardware_interface/PositionJointInterface</hardwareInterface>
            <mechanicalReduction>1</mechanicalReduction>
        </actuator>
    </transmission>
    <transmission name="trans_joint6">
        <type>transmission_interface/SimpleTransmission</type>
        <joint name="joint6">
            <hardwareInterface>hardware_interface/PositionJointInterface</hardwareInterface>
        </joint>
        <actuator name="joint6_motor">
            <hardwareInterface>hardware_interface/PositionJointInterface</hardwareInterface>
            <mechanicalReduction>1</mechanicalReduction>
        </actuator>
    </transmission>
    <transmission name="trans_Gripper_Joint1">
        <type>transmission_interface/SimpleTransmission</type>
        <joint name="Gripper_Joint1">
            <hardwareInterface>hardware_interface/PositionJointInterface</hardwareInterface>
        </joint>
        <actuator name="Gripper_Joint1_motor">
            <hardwareInterface>hardware_interface/PositionJointInterface</hardwareInterface>
            <mechanicalReduction>1</mechanicalReduction>
        </actuator>
    </transmission>
    <transmission name="trans_Gripper_Joint2">
        <type>transmission_interface/SimpleTransmission</type>
        <joint name="Gripper_Joint2">
            <hardwareInterface>hardware_interface/PositionJointInterface</hardwareInterface>
        </joint>
        <actuator name="Gripper_Joint2_motor">
            <hardwareInterface>hardware_interface/PositionJointInterface</hardwareInterface>
            <mechanicalReduction>1</mechanicalReduction>
        </actuator>
    </transmission>
    <gazebo>
        <plugin name="gazebo_ros_control" filename="libgazebo_ros_control.so">
            <robotNamespace>/</robotNamespace>
        </plugin>
    </gazebo>
</robot>

